Workbook

Sheet Sheet1
A1: رقم السجل التجاري | B1: رقم العقد | C1: العميل | D1: Name of factories | E1: المدينة | F1: Mobile | G1: Phone | H1: Email | I1: Fax | J1: حالة العميل | K1: نوع الأرض | L1: حالة الإنشائية | M1: تاريخ البدء | N1: تاريخ الإنتهاء | O1: Area | P1: تاريخ إصدار السجل التجاري | Q1: الأنشطة الصناعية
A2: 1010239390 | B2: 801190 | C2: مصنع أسامة عبدالعزيز الدهيشي لهياكل السيارات | D2: Osama Abdul Aziz Al-Dahishi Factory for Car Bodies | E2: الخرج | F2: 0505450758 | G2: 0112416652 | H2: info@aldheeshi.com | I2: 0112440368 | J2: مفتوح | K2: صناعي | L2: منتج | M2: 2010-06-29 | N2: 2029-11-22 | O2: 10500 | P2: 2 | Q2: =VLOOKUP(B2,[1]Sheet1!$A$1:$F$6212,6,0) -> #N/A
A3: 1011000322 | B3: 805402 | C3: مصنع الجعيثن للصناعات الحديدية | D3: Al-Jeathen Factory for Steel Industries | E3: الخرج | F3: 0504270970 | G3: 0115500000 | H3: mubarak@aljeathen.com | I3: 0115510000 | J3: مفتوح | K3: صناعي | L3: لم يبدأ في التنفيذ | M3: 2014-11-16 | N3: 2034-04-12 | O3: 65818 | P3: 28546 | Q3: =VLOOKUP(B3,[1]Sheet1!$A$1:$F$6212,6,0) -> #N/A
A4: 1010402346 | B4: 805352 | C4: مصنع شركة الاتحاد الدوليه للصناعات المعدنية | D4: Al-Etihad International Co. Factory for Metal Industries | E4: الخرج | F4: 0594111120 | G4: 0114459027 | H4: vip_z55z@hotmail.com | I4: 0114459027 | J4: مفتوح | K4: صناعي | L4: متوقف عن الإنشاء | M4: 2014-11-03 | N4: 2034-03-30 | O4: 10484 | P4: 41662 | Q4: =VLOOKUP(B4,[1]Sheet1!$A$1:$F$6212,6,0) -> #N/A
A5: 1011022145 | B5: 805898 | C5: مصنع عبدالرحمن محمد الرويشد للمنتجات المعدنيه | D5: Abdel Rahman Mohamed Al-Ruwaished Factory for Metal Products | E5: الخرج | F5: 0553075709 | G5: 0115448339 | H5: rowish_acv@hotmail.com | I5: 0115453121 | J5: مفتوح | K5: صناعي | L5: متوقف عن الإنشاء | M5: 2015-02-24 | N5: 2034-07-21 | O5: 9322 | P5: 41837 | Q5: =VLOOKUP(B5,[1]Sheet1!$A$1:$F$6212,6,0) -> #N/A
A6: 1010225012 | B6: 804986 | C6: مصنع السعودية للأتوبيسات | D6: Saudi Bus Factory | E6: الرياض الأولى | F6: 0504488444 | G6: 0114484477 | H6: industry@owaidah.com.sa | I6: 0114469761 | J6: مفتوح | K6: صناعي | L6: منتج | M6: 2014-04-22 | N6: 2029-10-29 | O6: 8420 | P6: 39040 | Q6: =VLOOKUP(B6,[1]Sheet1!$A$1:$F$6212,6,0) -> #N/A
A7: 1010427174 | B7: 805522 | C7: هايل تريلور العربية السعودية المحدودة | D7: Saudi Arabia Hale Tralor Company Limited | E7: الرياض الثالثة | F7: 0535259069 | G7: 0535259069 | H7: smohammed@heiltrailer.com | I7: 0112187801 | J7: مفتوح | K7: مصنع جاهز | L7: منتج | M7: 2014-12-15 | N7: 2019-10-22 | O7: 2936 | P7: 41940 | Q7: =VLOOKUP(B7,[1]Sheet1!$A$1:$F$6212,6,0) -> #N/A
A8: 1010005675 | B8: 800357 | C8: مصنع المطرودي لهياكل السيارات | D8: Al-Matroudi Car Bodies Factory | E8: الرياض الثانية | F8: 0553222284 | G8: 0114981592 | H8: fahadsalah24@hotmail.com | I8: 0114980723 | J8: مفتوح | K8: صناعي | L8: منتج | M8: 2009-06-12 | N8: 2019-02-23 | O8: 16000 | P8: 2 | Q8: =VLOOKUP(B8,[1]Sheet1!$A$1:$F$6212,6,0) -> #N/A
A9: 4030086643 | B9: 30658 | C9: شركة الشمراني (مصنع مقطورات السحب والجر) | D9: Al-Shamrani company (Push-Pull Tractors Factory) | E9: جدة الأولى | F9: 0500006597 | G9: 0126378612 | H9: shamrany_jed@hotmail.com | I9: 0126080797 | J9: مفتوح | K9: صناعي | L9: منتج | M9: 2010-03-01 | N9: 2029-07-26 | O9: 11740 | P9: 33721 | Q9: =VLOOKUP(B9,[1]Sheet1!$A$1:$F$6212,6,0) -> #N/A
A10: 4030266121 | B10: 805014 | C10: مصنع إيثار لمعدات الإطفاء والسلامه | D10: Eysar Factory for Fire Extinguishing and Safety Equipment | E10: جدة الأولى | F10: 0582999999 | G10: 0126141667 | H10: faisal13456@gmail.com | I10: 0126141669 | J10: مفتوح | K10: صناعي | L10: منتج | M10: 2014-05-28 | N10: 2034-10-12 | O10: 7080 | P10: 41696 | Q10: =VLOOKUP(B10,[1]Sheet1!$A$1:$F$6212,6,0) -> #N/A
A11: 4030267606 | B11: 805102 | C11: مصتع مقطورات النامى | D11: Al-Namy Trailers Factory | E11: جدة الثالثة | F11: 0553444748 | G11: 0114713573 | H11: alnmi_99@hotmail.com | I11: 0114713573 | J11: مفتوح | K11: صناعي | L11: منتج | M11: 2014-07-09 | N11: 2033-12-04 | O11: 9000 | P11: 41718 | Q11: =VLOOKUP(B11,[1]Sheet1!$A$1:$F$6212,6,0) -> #N/A
A12: 4030154013 | B12: 803302 | C12: مصنع عبدالله محمد السعدي لانتاج هياكل المقطورات | D12: Abdullah Mohamed Al-Saadi Factory for Metal Industries | E12: جدة الثالثة | F12: 0555548989 | G12: 0126205050 | H12: f.m.aloufi@hotmail.com | I12: 026201059 | J12: مفتوح | K12: صناعي | L12: منتج | M12: 2012-10-13 | N12: 2032-03-09 | O12: 16890 | P12: 38413 | Q12: =VLOOKUP(B12,[1]Sheet1!$A$1:$F$6212,6,0) -> #N/A
A13: 4030137859 | B13: 803659 | C13: مصنع عبده زايد علي الشميري للصناعات المعدنية | D13: Abdo Zayed Ali Al-Shemeri Factory for Metal Industries | E13: جدة الثالثة | F13: 0505697584 | G13: 0126204915 | H13: alriyadh_consultant@yahoo.com | I13: 026204915 | J13: مفتوح | K13: صناعي | L13: مكتمل إنشائياً | M13: 2013-01-26 | N13: 2032-06-22 | O13: 9000 | P13: 37349 | Q13: =VLOOKUP(B13,[1]Sheet1!$A$1:$F$6212,6,0) -> #N/A
... A16: 1010111255 | B16: 801623 | C16: شركة المصنع السعودي لصناعات الصوف الصخري | D16: Saudi Rock Wool Factory | E16: الخرج | F16: 0509994555 | G16: 0112650034 | H16: eidi_sulaiman@sudirockwool.com | I16: 0112650089 | J16: مفتوح | K16: صناعي | L16: منتج | M16: 2011-01-19 | N16: 2030-06-15 | O16: 80455 | P16: 2 | Q16: =VLOOKUP(B16,[1]Sheet1!$A$1:$F$6212,6,0) -> #N/A
A17: 1010178847 | B17: 802891 | C17: مصنع أسلم أنصار أنصاري لانتاج اللحف والمخدات | D17: #N/A | E17: الخرج | F17: 0505491660 | G17: 0112985828 | H17: aansari5026@hotmail.com | I17: 0112985813 | J17: مفتوح | K17: صناعي | L17: متوقف عن الإنشاء | M17: 2012-04-12 | N17: 2030-11-08 | O17: 24115 | P17: 37451 | Q17: =VLOOKUP(B17,[1]Sheet1!$A$1:$F$6212,6,0) -> #N/A
A18: 1010301144 | B18: 802043 | C18: مصنع النسيج الإدريسي | D18: El-Idrissi Textile Co. | E18: الخرج | F18: 0552288390 | G18: 0114456608 | H18: im2006@yahoo.cpm | I18: 0114456608 | J18: مفتوح | K18: صناعي | L18: تجهيز خطوط الانتاج | M18: 2011-06-11 | N18: 2030-11-04 | O18: 5067 | P18: 2 | Q18: =VLOOKUP(B18,[1]Sheet1!$A$1:$F$6212,6,0) -> #N/A
A19: 1010280745 | B19: 801492 | C19: الشركة العربية لصناعة الأغطية والوسائد | D19: Arabian Company for Comforters and Pillows (ACCP) | E19: الرياض الثانية | F19: 0505405516 | G19: 0114982226 | H19: accp@satex.com.sa | I19: 0112411553 | J19: مفتوح | K19: صناعي | L19: منتج | M19: 2010-03-17 | N19: 2030-03-08 | O19: 7500 | P19: 2 | Q19: =VLOOKUP(B19,[1]Sheet1!$A$1:$F$6212,6,0) -> #N/A
A20: 1010083670 | B20: 20673 | C20: المصنع السعودي للشماغ | D20: Saudi Shemagh Factory | E20: الرياض الثانية | F20: 0509996786 | G20: 0114980558 | H20: alajlan2000@hotmail.com | I20: 0114980570 | J20: مفتوح | K20: صناعي | L20: منتج | M20: 1998-03-22 | N20: 2022-06-22 | O20: 22000 | P20: 2 | Q20: =VLOOKUP(B20,[1]Sheet1!$A$1:$F$6212,6,0) -> #N/A
A21: 1010142008 | B21: 20571 | C21: المصنع الوطني لخيوط البوليستر | D21: National Polyester Fiber Factory | E21: الرياض الثانية | F21: 0505559335 | G21: 0114982250 | H21: info@ayed-sa.com | I21: 0114982246 | J21: مفتوح | K21: صناعي | L21: منتج | M21: 1997-01-26 | N21: 2021-04-28 | O21: 2500 | P21: 2 | Q21: =VLOOKUP(B21,[1]Sheet1!$A$1:$F$6212,6,0) -> #N/A
A22: 1010073685 | B22: 800788 | C22: شركة العبداللطيف للاستثمار الصناعي | D22: Al-Abdullatif Industrial Investment Company | E22: الرياض الثانية | F22: 0505757403 | G22: 0112658888 | H22: jaber@carpets.com | I22: 0112659999 | J22: مفتوح | K22: صناعي | L22: منتج | M22: 2009-09-30 | N22: 2029-02-23 | O22: 90586 | P22: 32777 | Q22: =VLOOKUP(B22,[1]Sheet1!$A$1:$F$6212,6,0) -> #N/A
A23: 1010167895 | B23: 20561 | C23: شركة العبيكان للمنسوجات التقنية | D23: Obeikan Technical Fabrics Co. (OTF) | E23: الرياض الثانية | F23: 0541244376 | G23: 0112653533 | H23: zayed@obeikan.com.sa | I23: 0112653438 | J23: مفتوح | K23: صناعي | L23: منتج | M23: 1999-07-14 | N23: 2023-10-15 | O23: 16800 | P23: 36546 | Q23: =VLOOKUP(B23,[1]Sheet1!$A$1:$F$6212,6,0) -> #N/A
A24: 1010056407 | B24: 20437 | C24: شركة بادية للغزل والنسيج | D24: Badia Spinning & Weaving Co. | E24: الرياض الثانية | F24: 0509997013 | G24: 0112652156 | H24: info@badia.com.sa | I24: 0112652157 | J24: مفتوح | K24: صناعي | L24: منتج | M24: 2010-09-27 | N24: 2030-02-20 | O24: 11685 | P24: 31032 | Q24: =VLOOKUP(B24,[1]Sheet1!$A$1:$F$6212,6,0) -> #N/A
A25: 1010127521 | B25: 20733 | C25: شركة خلدون الصناعية (مصنع النسيج والتطريز) | D25: Khaldoun Industrial Co. (Weaving & embroidery Factory) | E25: الرياض الثانية | F25: 0505479526 | G25: 0114981410 | H25: khaldoon_factory@yahoo.com | I25: 0114981304 | J25: مفتوح | K25: صناعي | L25: منتج | M25: 1995-01-28 | N25: 2019-05-01 | O25: 3100 | P25: 34562 | Q25: =VLOOKUP(B25,[1]Sheet1!$A$1:$F$6212,6,0) -> #N/A
A26: 1010068363 | B26: 805460 | C26: شركة سافي الدولية المحدودة | D26: Safi Leather Factory | E26: الرياض الثانية | F26: 0504675308 | G26: 0112651591 | H26: safyleather@hotmail.com | I26: 0112651590 | J26: مفتوح | K26: صناعي | L26: منتج | M26: 2014-11-03 | N26: 2016-11-03 | O26: 10186 | P26: 2 | Q26: =VLOOKUP(B26,[1]Sheet1!$A$1:$F$6212,6,0) -> #N/A
A27: 1010163897 | B27: 290085 | C27: شركة مصنع أحمد محمد بخاري وشريكه للوسائد والشراشف | D27: Ahmed Mohammed Bukari & Partner Factory Company for Pillows and Bedspreads | E27: الرياض الثانية | F27: 0504494875 | G27: 0112653633 | H27: ama_bukhari@yahoo.com | I27: 0112653635 | J27: مفتوح | K27: صناعي | L27: منتج | M27: 2008-02-04 | N27: 2030-05-27 | O27: 4224 | P27: 2 | Q27: =VLOOKUP(B27,[1]Sheet1!$A$1:$F$6212,6,0) -> #N/A
A28: 1010046659 | B28: 20392 | C28: مصنع أديم للازياء الموحدة | D28: Adeem Uniforms Company | E28: الرياض الثانية | F28: 0504161615 | G28: 0114771803 | H28: adeemadeem@hotmail.com | I28: 0114767896 | J28: مفتوح | K28: صناعي | L28: منتج | M28: 2004-01-18 | N28: 2028-04-20 | O28: 6120 | P28: 30272 | Q28: =VLOOKUP(B28,[1]Sheet1!$A$1:$F$6212,6,0) -> #N/A
A29: 1010143752 | B29: 20707 | C29: مصنع الياف لأنتاج الملابس الجاهزة والعباءات | D29: Alyaf Readymade Garments and Gowns Manufacturing Factory | E29: الرياض الثانية | F29: 0505206475 | G29: 0114982962 | H29: alyafgorp@yahoo.com | I29: 0114986482 | J29: مفتوح | K29: صناعي | L29: منتج | M29: 2006-06-28 | N29: 2030-09-29 | O29: 1716 | P29: 2 | Q29: =VLOOKUP(B29,[1]Sheet1!$A$1:$F$6212,6,0) -> #N/A
... A39: 4650039414 | B39: 802588 | C39: مصنع طيبة للسجاد | D39: Tiba Carpet Factory | E39: المدينة المنورة | F39: 0507999111 | G39: 0148415321 | H39: teiba-carpet@hotmail.com | I39: 048415321 | J39: مفتوح | K39: صناعي | L39: تحت الإنشاء | M39: 2012-01-14 | N39: 2031-06-09 | O39: 9226 | P39: 39291 | Q39: =VLOOKUP(B39,[1]Sheet1!$A$1:$F$6212,6,0) -> #N/A
A40: 4650082887 | B40: 805212 | C40: مصنع عبدالعزيز عبدالرحمن العياف للمشالح والفراء | D40: #N/A | E40: المدينة المنورة | F40: 0555708449 | G40: 0127325591 | H40: ayyaf2014@hotmail.com | I40: 0127325294 | J40: مفتوح | K40: صناعي | L40: منتج | M40: 2014-08-26 | N40: 2034-01-20 | O40: 4637 | P40: 42970 | Q40: =VLOOKUP(B40,[1]Sheet1!$A$1:$F$6212,6,0) -> #N/A
A41: 4650042009 | B41: 801690 | C41: مصنع مشالح البدر | D41: Mashaleh Elbadr Factory | E41: المدينة المنورة | F41: 0555322001 | G41: 0148253089 | H41: info@m-albader.com | I41: 048253089 | J41: مفتوح | K41: صناعي | L41: منتج | M41: 2010-12-10 | N41: 2028-05-27 | O41: 4320 | P41: 2 | Q41: =VLOOKUP(B41,[1]Sheet1!$A$1:$F$6212,6,0) -> #N/A
A42: 4650038090 | B42: 801092 | C42: مصنع نور طيبة للأحذية | D42: Noor Tiba Shoes Factory | E42: المدينة المنورة | F42: 0503335822 | G42: 0148488260 | H42: basem822@windowslive.com | I42: 048488260 | J42: مفتوح | K42: صناعي | L42: تحت الإنشاء | M42: 2009-03-19 | N42: 2028-08-12 | O42: 4608 | P42: 39060 | Q42: =VLOOKUP(B42,[1]Sheet1!$A$1:$F$6212,6,0) -> #N/A
A43: 4650047267 | B43: 801266 | C43: مصنع يوسف على المغذوي لمنتجات البوليستارين | D43: Yusuf Ali Al-Maghzaoui Factory for Polystyrene Products | E43: المدينة المنورة | F43: 0505314894 | G43: 0148408070 | H43: yosf-fac@hotmail.com | I43: 048408070 | J43: مفتوح | K43: صناعي | L43: منتج | M43: 2010-07-18 | N43: 2029-12-11 | O43: 6912 | P43: 2 | Q43: =VLOOKUP(B43,[1]Sheet1!$A$1:$F$6212,6,0) -> #N/A
A44: 5855032186 | B44: 805238 | C44: مصنع تركيه علي ال فايع للملابس الجاهزه | D44: Turkieh Ali Al Faye Factory for Garments | E44: جازان | F44: 0554513131 | G44: 0172353309 | H44: h.saif.5@hotmail.com | I44: 0172354037 | J44: مفتوح | K44: صناعي | L44: لم يبدأ في التنفيذ | M44: 2014-09-17 | N44: 2034-02-11 | O44: 5477 | P44: 39924 | Q44: =VLOOKUP(B44,[1]Sheet1!$A$1:$F$6212,6,0) -> #N/A
A45: 4030095441 | B45: 30502 | C45: المصنع السعودي لتقنية الخيوط والنسيج | D45: Saudi Yarn and Knitting Technology Factory | E45: جدة الأولى | F45: 0557603734 | G45: 0126351731 | H45: syntech@nafa.net | I45: 0126380866 | J45: مفتوح | K45: صناعي | L45: منتج | M45: 1994-07-25 | N45: 2018-10-25 | O45: 50050 | P45: 34098 | Q45: =VLOOKUP(B45,[1]Sheet1!$A$1:$F$6212,6,0) -> #N/A
A46: 4030012551 | B46: 30605 | C46: شركة المصنع الوطني لعبوات البوليستايرين (ستايرينباك) | D46: National Factory for Polystyrene Packs Co. Ltd (StyrenPack) | E46: جدة الأولى | F46: 0505627479 | G46: 0126360517 | H46: styrene@styrenpack.com | I46: 0126378964 | J46: مفتوح | K46: صناعي | L46: منتج | M46: 2009-12-31 | N46: 2029-05-26 | O46: 8000 | P46: 28296 | Q46: =VLOOKUP(B46,[1]Sheet1!$A$1:$F$6212,6,0) -> #N/A
A47: 4030013068 | B47: 800523 | C47: شركة مصانع مفروشات ابو السعود | D47: Abul Saud Furniture Factories Co. | E47: جدة الأولى | F47: 0505608806 | G47: 0126373075 | H47: sales@abouseoud.com | I47: 026354451 | J47: مفتوح | K47: صناعي | L47: منتج | M47: 2009-05-13 | N47: 2019-01-23 | O47: 10000 | P47: 2 | Q47: =VLOOKUP(B47,[1]Sheet1!$A$1:$F$6212,6,0) -> #N/A
A48: 4030143934 | B48: 30976 | C48: شركة مصنع المستلزمات الحديثة للنسيج | D48: Modern Textile Supplies Factory Company | E48: جدة الأولى | F48: 0564061001 | G48: 0126365252 | H48: hadeel@asiig.com | I48: 0126367771 | J48: مفتوح | K48: صناعي | L48: منتج | M48: 2013-12-17 | N48: 2023-08-29 | O48: 8250 | P48: 1/1/53 0:00 | Q48: =VLOOKUP(B48,[1]Sheet1!$A$1:$F$6212,6,0) -> #N/A
A49: 4030115974 | B49: 30800 | C49: شركة مصنع جدة للخيوط الصناعية | D49: Jeddah Industrial Yarn Factory Co. | E49: جدة الأولى | F49: 0552121242 | G49: 0126370888 | H49: ali.katheri@al-sorayai.com | I49: 0126380813 | J49: مفتوح | K49: صناعي | L49: منتج | M49: 1997-03-02 | N49: 2020-06-14 | O49: 16875 | P49: 35028 | Q49: =VLOOKUP(B49,[1]Sheet1!$A$1:$F$6212,6,0) -> #N/A
A50: 4030115974 | B50: 30885 | C50: شركة مصنع جدة للخيوط الصناعية | D50: Jeddah Industrial Yarn Factory Co. | E50: جدة الأولى | F50: 0552121242 | G50: 0126370888 | H50: ali.katheri@al-sorayai.com | I50: 0126380813 | J50: مفتوح | K50: صناعي | L50: منتج | M50: 2006-07-03 | N50: 2030-10-04 | O50: 1125 | P50: 35028 | Q50: =VLOOKUP(B50,[1]Sheet1!$A$1:$F$6212,6,0) -> #N/A
A51: 4030115974 | B51: 30994 | C51: شركة مصنع جدة للخيوط الصناعية | D51: Jeddah Industrial Yarn Factory Co. | E51: جدة الأولى | F51: 0552121242 | G51: 0126370888 | H51: ali.katheri@al-sorayai.com | I51: 0126380813 | J51: مفتوح | K51: صناعي | L51: منتج | M51: 2006-08-20 | N51: 2030-11-21 | O51: 3720 | P51: 35028 | Q51: =VLOOKUP(B51,[1]Sheet1!$A$1:$F$6212,6,0) -> #N/A
...

Sheet ورقة1
A1: رقم العقد | B1: العميل | C1: Mobile | D1: Phone | E1: Email | F1: Fax | G1: المدينة | H1: حالة العميل | I1: نوع الأرض | J1: حالة الإنشائية | K1: تاريخ البدء | L1: تاريخ الإنتهاء | M1: Area | N1: رقم السجل التجاري | O1: تاريخ إصدار السجل التجاري | P1: الأنشطة الصناعية
A2: 801190 | B2: مصنع أسامة عبدالعزيز الدهيشي لهياكل السيارات | C2: 0505450758 | D2: 0112416652 | E2: info@aldheeshi.com | F2: 0112440368 | G2: الخرج | H2: مفتوح | I2: صناعي | J2: منتج | K2: 2010-06-29 | L2: 2029-11-22 | M2: 10500 | N2: 1010239390 | O2: 2 | P2: صنع المركبات ذات المحركات والمركبات المقطورة ونصف المقطورة | Q2: =VLOOKUP(N2,ورقة2!$A$1:$J$14632,3,0) -> Osama Abdul Aziz Al-Dahishi Factory for Car Bodies
A3: 805402 | B3: مصنع الجعيثن للصناعات الحديدية | C3: 0504270970 | D3: 0115500000 | E3: mubarak@aljeathen.com | F3: 0115510000 | G3: الخرج | H3: مفتوح | I3: صناعي | J3: لم يبدأ في التنفيذ | K3: 2014-11-16 | L3: 2034-04-12 | M3: 65818 | N3: 1011000322 | O3: 28546 | P3: صنع المركبات ذات المحركات والمركبات المقطورة ونصف المقطورة | Q3: =VLOOKUP(N3,ورقة2!$A$1:$J$14632,3,0) -> Al-Jeathen Factory for Steel Industries
A4: 805352 | B4: مصنع شركة الاتحاد الدوليه للصناعات المعدنية | C4: 0594111120 | D4: 0114459027 | E4: vip_z55z@hotmail.com | F4: 0114459027 | G4: الخرج | H4: مفتوح | I4: صناعي | J4: متوقف عن الإنشاء | K4: 2014-11-03 | L4: 2034-03-30 | M4: 10484 | N4: 1010402346 | O4: 41662 | P4: صنع المركبات ذات المحركات والمركبات المقطورة ونصف المقطورة | Q4: =VLOOKUP(N4,ورقة2!$A$1:$J$14632,3,0) -> Al-Etihad International Co. Factory for Metal Industries
A5: 805898 | B5: مصنع عبدالرحمن محمد الرويشد للمنتجات المعدنيه | C5: 0553075709 | D5: 0115448339 | E5: rowish_acv@hotmail.com | F5: 0115453121 | G5: الخرج | H5: مفتوح | I5: صناعي | J5: متوقف عن الإنشاء | K5: 2015-02-24 | L5: 2034-07-21 | M5: 9322 | N5: 1011022145 | O5: 41837 | P5: صنع المركبات ذات المحركات والمركبات المقطورة ونصف المقطورة | Q5: =VLOOKUP(N5,ورقة2!$A$1:$J$14632,3,0) -> Abdel Rahman Mohamed Al-Ruwaished Factory for Metal Products
A6: 804986 | B6: مصنع السعودية للأتوبيسات | C6: 0504488444 | D6: 0114484477 | E6: industry@owaidah.com.sa | F6: 0114469761 | G6: الرياض الأولى | H6: مفتوح | I6: صناعي | J6: منتج | K6: 2014-04-22 | L6: 2029-10-29 | M6: 8420 | N6: 1010225012 | O6: 39040 | P6: صنع المركبات ذات المحركات والمركبات المقطورة ونصف المقطورة | Q6: =VLOOKUP(N6,ورقة2!$A$1:$J$14632,3,0) -> Saudi Bus Factory
A7: 805522 | B7: هايل تريلور العربية السعودية المحدودة | C7: 0535259069 | D7: 0535259069 | E7: smohammed@heiltrailer.com | F7: 0112187801 | G7: الرياض الثالثة | H7: مفتوح | I7: مصنع جاهز | J7: منتج | K7: 2014-12-15 | L7: 2019-10-22 | M7: 2936 | N7: 1010427174 | O7: 41940 | P7: صنع المركبات ذات المحركات والمركبات المقطورة ونصف المقطورة | Q7: =VLOOKUP(N7,ورقة2!$A$1:$J$14632,3,0) -> Saudi Arabia Hale Tralor Company Limited
A8: 800357 | B8: مصنع المطرودي لهياكل السيارات | C8: 0553222284 | D8: 0114981592 | E8: fahadsalah24@hotmail.com | F8: 0114980723 | G8: الرياض الثانية | H8: مفتوح | I8: صناعي | J8: منتج | K8: 2009-06-12 | L8: 2019-02-23 | M8: 16000 | N8: 1010005675 | O8: 2 | P8: صنع المركبات ذات المحركات والمركبات المقطورة ونصف المقطورة | Q8: =VLOOKUP(N8,ورقة2!$A$1:$J$14632,3,0) -> Al-Matroudi Car Bodies Factory
A9: 30658 | B9: شركة الشمراني (مصنع مقطورات السحب والجر) | C9: 0500006597 | D9: 0126378612 | E9: shamrany_jed@hotmail.com | F9: 0126080797 | G9: جدة الأولى | H9: مفتوح | I9: صناعي | J9: منتج | K9: 2010-03-01 | L9: 2029-07-26 | M9: 11740 | N9: 4030086643 | O9: 33721 | P9: صنع المركبات ذات المحركات والمركبات المقطورة ونصف المقطورة | Q9: =VLOOKUP(N9,ورقة2!$A$1:$J$14632,3,0) -> Al-Shamrani company (Push-Pull Tractors Factory)
A10: 805014 | B10: مصنع إيثار لمعدات الإطفاء والسلامه | C10: 0582999999 | D10: 0126141667 | E10: faisal13456@gmail.com | F10: 0126141669 | G10: جدة الأولى | H10: مفتوح | I10: صناعي | J10: منتج | K10: 2014-05-28 | L10: 2034-10-12 | M10: 7080 | N10: 4030266121 | O10: 41696 | P10: صنع المركبات ذات المحركات والمركبات المقطورة ونصف المقطورة | Q10: =VLOOKUP(N10,ورقة2!$A$1:$J$14632,3,0) -> Eysar Factory for Fire Extinguishing and Safety Equipment
A11: 805102 | B11: مصتع مقطورات النامى | C11: 0553444748 | D11: 0114713573 | E11: alnmi_99@hotmail.com | F11: 0114713573 | G11: جدة الثالثة | H11: مفتوح | I11: صناعي | J11: منتج | K11: 2014-07-09 | L11: 2033-12-04 | M11: 9000 | N11: 4030267606 | O11: 41718 | P11: صنع معدات النقل الاخرى | Q11: =VLOOKUP(N11,ورقة2!$A$1:$J$14632,3,0) -> Al-Namy Trailers Factory
A12: 803302 | B12: مصنع عبدالله محمد السعدي لانتاج هياكل المقطورات | C12: 0555548989 | D12: 0126205050 | E12: f.m.aloufi@hotmail.com | F12: 026201059 | G12: جدة الثالثة | H12: مفتوح | I12: صناعي | J12: منتج | K12: 2012-10-13 | L12: 2032-03-09 | M12: 16890 | N12: 4030154013 | O12: 38413 | P12: صنع المركبات ذات المحركات والمركبات المقطورة ونصف المقطورة | Q12: =VLOOKUP(N12,ورقة2!$A$1:$J$14632,3,0) -> Abdullah Mohamed Al-Saadi Factory for Metal Industries
A13: 803659 | B13: مصنع عبده زايد علي الشميري للصناعات المعدنية | C13: 0505697584 | D13: 0126204915 | E13: alriyadh_consultant@yahoo.com | F13: 026204915 | G13: جدة الثالثة | H13: مفتوح | I13: صناعي | J13: مكتمل إنشائياً | K13: 2013-01-26 | L13: 2032-06-22 | M13: 9000 | N13: 4030137859 | O13: 37349 | P13: صنع المركبات ذات المحركات والمركبات المقطورة ونصف المقطورة | Q13: =VLOOKUP(N13,ورقة2!$A$1:$J$14632,3,0) -> Abdo Zayed Ali Al-Shemeri Factory for Metal Industries
... A167: 803505 | B167: مصنع ماجد عبدالله النهدي للمنتجات الاسفلتيه | C167: 0509999925 | D167: 0114769583 | E167: Majed-alshabibi@hotmail.com | F167: 0114769583 | G167: الخرج | H167: مفتوح | I167: صناعي | J167: متوقف عن الإنشاء | K167: 2012-12-15 | L167: 2032-05-11 | M167: 10443 | N167: 1010351304 | O167: 41181 | P167: الصناعات التحويلية الأخرى | Q167: =VLOOKUP(N167,ورقة2!$A$1:$J$14632,3,0) -> Majed Abdullah Nahdi Factory for Asphalt Products
A168: 801945 | B168: مصنع مرو الرياض للكيماويات | C168: 0504441840 | D168: 0114876009 | E168: sultan.mhmd390@gmail.com | F168: 0114876009 | G168: الخرج | H168: مفتوح | I168: صناعي | J168: تحت الإنشاء | K168: 2011-04-21 | L168: 2030-09-15 | M168: 11250 | N168: 8746/ت | O168: 40328 | P168: صنع المواد الكيميائية والمنتجات الكيميائية | Q168: =VLOOKUP(N168,ورقة2!$A$1:$J$14632,3,0) -> Maru Riyadh Chemicals Factory
A169: 803785 | B169: مصنع مستوى الهدف للأسمدة | C169: 0505101060 | D169: 0114955627 | E169: jalamneh@hadaflevel.com.sa | F169: 0114958689 | G169: الخرج | H169: مفتوح | I169: صناعي | J169: منتج | K169: 2013-03-12 | L169: 2032-08-07 | M169: 13910 | N169: 1010223127 | O169: 38971 | P169: صنع المواد الكيميائية والمنتجات الكيميائية | Q169: =VLOOKUP(N169,ورقة2!$A$1:$J$14632,3,0) -> Al-Hadaf Level Factory for Fertilizers
A170: 805160 | B170: مصنع موقفة للعوازل الاسفلتية | C170: 0555227044 | D170: 0114211687 | E170: naif0555227044@gmail.com | F170: 014211687 | G170: الخرج | H170: مفتوح | I170: صناعي | J170: لم يبدأ في التنفيذ | K170: 2014-07-23 | L170: 2033-12-18 | M170: 11044 | N170: 1010155159 | O170: 36397 | P170: الصناعات التحويلية الأخرى | Q170: =VLOOKUP(N170,ورقة2!$A$1:$J$14632,3,0) -> Mawkefa Factory for Asphalt Insulations
A171: 802585 | B171: مصنع نبات الأرض لإنتاج الاسمدة والمخصبات والمبيدات الحيوية | C171: 0595959512 | D171: 0114380940 | E171: a_algasem@hotmail.com | F171: 0112132603 | G171: الخرج | H171: مفتوح | I171: صناعي | J171: تحت الإنشاء | K171: 2012-01-10 | L171: 2031-06-05 | M171: 10398 | N171: 1010208095 | O171: 40607 | P171: صنع المواد الكيميائية والمنتجات الكيميائية | Q171: =VLOOKUP(N171,ورقة2!$A$1:$J$14632,3,0) -> Nabat Al-Ard Factory for the Production of Fertilizers and Bio-pesticides
A172: 805976 | B172: مصنع نقا للدهانات و المعاجين | C172: 0555439269 | D172: 0114952600 | E172: info@naqapaint.com | F172: 0114953325 | G172: الخرج | H172: مفتوح | I172: صناعي | J172: تحت الإنشاء | K172: 2015-03-24 | L172: 2034-08-18 | M172: 5060 | N172: 1011023256 | O172: 42059 | P172: صنع المواد الكيميائية والمنتجات الكيميائية | Q172: =VLOOKUP(N172,ورقة2!$A$1:$J$14632,3,0) -> Naqa Factory for Paints and Pastes
A173: 805827 | B173: مصنع نهر الصناعات لسليكات الصوديوم | C173: 0505818016 | D173: 0114563790 | E173: ali924444@gmil.com | F173: 0114536790 | G173: الخرج | H173: مفتوح | I173: صناعي | J173: لم يبدأ في التنفيذ | K173: 2015-01-28 | L173: 2034-06-24 | M173: 11249 | N173: 1011022829 | O173: 41963 | P173: صنع المواد الكيميائية والمنتجات الكيميائية | Q173: =VLOOKUP(N173,ورقة2!$A$1:$J$14632,3,0) -> Nahr Al-Senaat Factory for Sodium Silicate
A174: 805806 | B174: مصنع نوء الخير لكيماويات معالجة المياه | C174: 0504803464 | D174: 0114953041 | E174: naw_chemicals@hotmail.com | F174: 0114953041 | G174: الخرج | H174: مفتوح | I174: صناعي | J174: تحت الإنشاء | K174: 2015-02-05 | L174: 2034-07-02 | M174: 6815 | N174: 1011022595 | O174: 41933 | P174: صنع المواد الكيميائية والمنتجات الكيميائية | Q174: =VLOOKUP(N174,ورقة2!$A$1:$J$14632,3,0) -> Nou' El-Khair Factory for Water Treatment Chemicals
A175: 803312 | B175: مصنع وائل حسين سلامة للدهانات | C175: 0555308801 | D175: 0114001441 | E175: salamsafran@hotmail.com | F175: 0114235034 | G175: الخرج | H175: مفتوح | I175: صناعي | J175: تحت الإنشاء | K175: 2012-10-14 | L175: 2032-03-10 | M175: 5715 | N175: 1010305491 | O175: 2 | P175: صنع المواد الكيميائية والمنتجات الكيميائية | Q175: =VLOOKUP(N175,ورقة2!$A$1:$J$14632,3,0) -> Wael Hussein Salama Factory for Paints
A176: 40121 | B176: الشركة السعودية للدهانات الصناعية | C176: 0536000062 | D176: 0138472299 | E176: info@sipco.com.sa | F176: 0138473780 | G176: الدمام الأولى | H176: مفتوح | I176: صناعي | J176: منتج | K176: 2006-01-30 | L176: 2030-05-02 | M176: 16250 | N176: 2050011750 | O176: -53688 | P176: صنع المواد الكيميائية والمنتجات الكيميائية | Q176: =VLOOKUP(N176,ورقة2!$A$1:$J$14632,3,0) -> Saudi Industrial Paints Company (SIPCO)
A177: 40083 | B177: الشركة العربية للمعادن والكيماويات | C177: 0559550725 | D177: 0138472187 | E177: mshahrani@misaudi.com | F177: 0138473608 | G177: الدمام الأولى | H177: مفتوح | I177: صناعي | J177: منتج | K177: 2000-10-12 | L177: 2025-01-14 | M177: 28000 | N177: 2050004593 | O177: 2 | P177: صنع منتجات المعادن المشكلة، باستثناء الالات والمعدات | Q177: =VLOOKUP(N177,ورقة2!$A$1:$J$14632,3,0) -> Arab Co. for Metal & Chemicals
A178: 40038 | B178: المصنع الحديث للحديد والشكمانات | C178: 0505876530 | D178: 0138473320 | E178: e-steel@hotmail.com | F178: 0138473320 | G178: الدمام الأولى | H178: مفتوح | I178: صناعي | J178: منتج | K178: 2003-01-13 | L178: 2027-04-16 | M178: 5580 | N178: 2050046046 | O178: 38159 | P178: صنع منتجات المعادن اللافلزية الأخرى | Q178: =VLOOKUP(N178,ورقة2!$A$1:$J$14632,3,0) -> Modern Exhaust Pipe & Iron Factory
A179: 40064 | B179: المصنع السعودي لأكياس التعبئة | C179: 0599968959 | D179: 0138472115 | E179: azahrani@almoajilholding.com | F179: 0138341513 | G179: الدمام الأولى | H179: مفتوح | I179: صناعي | J179: منتج | K179: 1999-10-01 | L179: 2024-01-02 | M179: 11144 | N179: 2050015798 | O179: 31278 | P179: صنع منتجات المطاط والبلاستك | Q179: =VLOOKUP(N179,ورقة2!$A$1:$J$14632,3,0) -> Saudi Gas Cylinder Factory
A180: 40139 | B180: شركة اصباغ همبل العربية السعودية | C180: 0550660011 | D180: 0138471919 | E180: yual@sa.hempel.com | F180: 0138471816 | G180: الدمام الأولى | H180: مفتوح | I180: صناعي | J180: متوقف عن الإنتاج | K180: 2003-04-19 | L180: 2027-07-20 | M180: 20338 | N180: 2050002792 | O180: 26695 | P180: صنع المواد الكيميائية والمنتجات الكيميائية | Q180: =VLOOKUP(N180,ورقة2!$A$1:$J$14632,3,0) -> Hempel Paints (Saudi Arabia) Co.
... A182: 40051 | B182: شركة الصناعات الكيماوية للبناء المحدودة | C182: 0555160883 | D182: 0138471779 | E182: hsaleh@gerflorme.com | F182: 0138471781 | G182: الدمام الأولى | H182: مفتوح | I182: صناعي | J182: منتج | K182: 2000-08-23 | L182: 2024-11-24 | M182: 17522 | N182: 2050076959 | O182: 2 | P182: صنع المواد الكيميائية والمنتجات الكيميائية | Q182: =VLOOKUP(N182,ورقة2!$A$1:$J$14632,3,0) -> Chemical Industries Co. Ltd. For Construction
A183: 40122 | B183: شركة المحولات السعودية المحدودة | C183: 0550502459 | D183: 0138472030 | E183: hanik@sauditransformers.com | F183: 0138471718 | G183: الدمام الأولى | H183: مفتوح | I183: صناعي | J183: منتج | K183: 2007-04-25 | L183: 2027-09-08 | M183: 24375 | N183: 001/205006 | O183: 2 | P183: صنع المعدات الكهربائية | Q183: =VLOOKUP(N183,ورقة2!$A$1:$J$14632,3,0) -> Saudi Transformer Co. Ltd.
A184: 40111 | B184: شركة بارويد العربية السعودية المحدودة | C184: 0500508409 | D184: 0138473888 | E184: b_aroid@hotmail.com | F184: 0138472143 | G184: الدمام الأولى | H184: مفتوح | I184: صناعي | J184: منتج | K184: 2001-07-19 | L184: 2025-10-19 | M184: 35000 | N184: 2050004457 | O184: 2 | P184: صنع منتجات المعادن المشكلة، باستثناء الالات والمعدات | Q184: =VLOOKUP(N184,ورقة2!$A$1:$J$14632,3,0) -> Baroid Saudi Arabia Co. Ltd.
A185: 40001 | B185: شركة تنهات للتعدين | C185: 0504684002 | D185: 0138473600 | E185: factory@tanhatmining.com | F185: 0138473600 | G185: الدمام الأولى | H185: مفتوح | I185: صناعي | J185: منتج | K185: 2001-09-08 | L185: 2025-12-10 | M185: 14875 | N185: 2050025945 | O185: 34175 | P185: صنع منتجات المعادن المشكلة، باستثناء الالات والمعدات | Q185: =VLOOKUP(N185,ورقة2!$A$1:$J$14632,3,0) -> Tenhat Mining Co.
A186: 40032 | B186: شركة سيجما السعودية للدهانات المحدودة | C186: 0503848025 | D186: 0138471734 | E186: sami.marzooq@sigmapaints.com | F186: 0138471734 | G186: الدمام الأولى | H186: مفتوح | I186: صناعي | J186: منتج | K186: 2005-03-27 | L186: 2029-06-28 | M186: 14194 | N186: 2050009638 | O186: 2 | P186: صنع المواد الكيميائية والمنتجات الكيميائية | Q186: =VLOOKUP(N186,ورقة2!$A$1:$J$14632,3,0) -> Sigma Paints Saudi Arabia Co., Ltd.
A187: 40076 | B187: شركة نابكو الحديثة للمنتوجات البلاستيك | C187: 0504823990 | D187: 0138473040 | E187: adahan@napcogroup.com | F187: 0138471484 | G187: الدمام الأولى | H187: مفتوح | I187: صناعي | J187: منتج | K187: 2001-12-22 | L187: 2026-03-25 | M187: 8308 | N187: 2050024798 | O187: 2 | P187: صنع منتجات المطاط والبلاستك | Q187: =VLOOKUP(N187,ورقة2!$A$1:$J$14632,3,0) -> NAPCO Modern Plastic Products Company
A188: 40063 | B188: مصنع الاسيد الحديث | C188: 0550500226 | D188: 0138472121 | E188: mail@modernacid.com | F188: 0138472121 | G188: الدمام الأولى | H188: مفتوح | I188: صناعي | J188: متوقف عن الإنتاج | K188: 1999-05-21 | L188: 2023-08-21 | M188: 2400 | N188: 2050034044 | O188: 2 | P188: صنع المواد الكيميائية والمنتجات الكيميائية | Q188: =VLOOKUP(N188,ورقة2!$A$1:$J$14632,3,0) -> Al-Asid Modern Company
A189: 804930 | B189: مصنع المنيوم الجزيرة | C189: 0553111471 | D189: 0138472040 | E189: info@alumjaz.com | F189: 0138473927 | G189: الدمام الأولى | H189: مفتوح | I189: صناعي | J189: منتج | K189: 2014-04-08 | L189: 2023-12-20 | M189: 5222 | N189: 2050045913 | O189: 2 | P189: صنع منتجات المعادن المشكلة، باستثناء الالات والمعدات | Q189: =VLOOKUP(N189,ورقة2!$A$1:$J$14632,3,0) -> Al-Jazirah Aluminum Plant
A190: 804921 | B190: مصنع عبداللة هاشم للمعدات والغازات | C190: 0556691414 | D190: 0138471517 | E190: salami@er.ahg.com.sa | F190: 0138471764 | G190: الدمام الأولى | H190: مفتوح | I190: صناعي | J190: منتج | K190: 2014-04-07 | L190: 2024-12-07 | M190: 18385 | N190: 2050024268 | O190: 33909 | P190: صنع المواد الكيميائية والمنتجات الكيميائية | Q190: =VLOOKUP(N190,ورقة2!$A$1:$J$14632,3,0) -> Abdullah Hashim Factory for Equipment and Gases
A191: 40002 | B191: مصنع كيماويات مواد البناء | C191: 0505889479 | D191: 0138471450 | E191: moussa@cmci-sa.com | F191: 0138471575 | G191: الدمام الأولى | H191: مفتوح | I191: صناعي | J191: منتج | K191: 2006-12-09 | L191: 2031-03-11 | M191: 2292 | N191: 2050028294 | O191: 2 | P191: صنع المواد الكيميائية والمنتجات الكيميائية | Q191: =VLOOKUP(N191,ورقة2!$A$1:$J$14632,3,0) -> Construction Materials Chemicals Factory
A192: 290237 | B192: مصنع كيماويات مواد البناء | C192: 0505889479 | D192: 0138471450 | E192: moussa@cmci-sa.com | F192: 0138471575 | G192: الدمام الأولى | H192: مفتوح | I192: صناعي | J192: منتج | K192: 2008-03-30 | L192: 2030-07-22 | M192: 8640 | N192: 2050028294 | O192: 2 | P192: صنع المواد الكيميائية والمنتجات الكيميائية | Q192: =VLOOKUP(N192,ورقة2!$A$1:$J$14632,3,0) -> Construction Materials Chemicals Factory
A193: 50076 | B193: اراسكو للصناعات الكيميائية | C193: 0506014991 | D193: 0138123451 | E193: archem@arasco.com | F193: 0138123133 | G193: الدمام الثانية | H193: مفتوح | I193: صناعي | J193: منتج | K193: 2001-05-14 | L193: 2025-08-13 | M193: 12400 | N193: 2050037275 | O193: 2 | P193: صنع المواد الكيميائية والمنتجات الكيميائية | Q193: =VLOOKUP(N193,ورقة2!$A$1:$J$14632,3,0) -> NULL
A194: 50476 | B194: الشركة السعودية لانتاج مواد النظافة | C194: 0559266711 | D194: 0138121135 | E194: raddad@sidco.com.sa | F194: 0138123336 | G194: الدمام الثانية | H194: مفتوح | I194: صناعي | J194: منتج | K194: 2003-12-24 | L194: 2028-03-26 | M194: 15000 | N194: 2050006900 | O194: 28913 | P194: صنع المواد الكيميائية والمنتجات الكيميائية | Q194: =VLOOKUP(N194,ورقة2!$A$1:$J$14632,3,0) -> Saudi Industrial Detergents Company (SIDCO)
...

Sheet ورقة2
A1: رقم السجل التجاري | B1: اسم العميل | C1: اسم العميل - انجليزي
A2: 1010073387 | B2: شركة انارة المحدودة | C2: NULL
A3: 2257024803 | B3: شركة عبدالله وخالد عبدالرحمن الشعيبي للتجارة ةالصناعة | C3: Al Shoaibi Plastic Factory
A4: 4030165161 | B4: مصنع عبدالرحمن حسين منصور الشريف لقوالب ومكائن البلك | C4: NULL
A5: NULL | B5: مصنع مملكة الحلويات والشوكولاته والسكاكر والبسكويت | C5: NULL
A6: 4030158088 | B6: المصنع السعودي للقوالب المعدنية | C6: Saudi Factory for Metal Molds
A7: 2257038479 | B7: مصنع خليفة خليفة الهاشل للأسلاك الكهربائية | C7: NULL
A8: 1010049775 | B8: مصنع خلف سعد المطيري للمنتجات المعدنيه | C8: Khalaf Saad Al-Mutairi Factory for Metal Products
A9: 1010038481 | B9: مصنع مركز القباني التجاري للحلويات | C9: Al-Qabbani Commercial Center Factory for Sweets
A10: 1010075948 | B10: مصنع مناع ظافر العمري للزجاج والمرايا | C10: Mannaa Zafer Al-Amri Factory for Glass & Mirrors
A11: 2257041043 | B11: مصنع الشروق للأسقف وشرائح الألمنيوم | C11: Al-Shorouq Factory for Aluminium Ceilings and Slides
A12: 3550024597 | B12: مصنع أسس الحديثة للمصاعد | C12: NULL
A13: 3550026947 | B13: مصنع عبدالله محمد حمدي للبلوك | C13: NULL
A14: 4350000678 | B14: مصنع عبدالعزيز علي الملحم للمناديل والكرتون | C14: NULL
A15: 5950011654 | B15: مصنع نطاقات الشرق الأوسط للبلوك والخرسانة الجاهزة | C15: NULL
A16: 4030135180 | B16: مصنع سامي محمد مصطفى ابو غانم للبلاستيك | C16: NULL
A17: 3350035796 | B17: مصنع/ محمد حمد صالح المقبل للثلاجات والبرادات | C17: NULL
... A185: 1010245946 | B185: مصنع شركة تقنية الطرق للأسفلت المحسن | C185: Road Technology co. factory for Enhanced Asphalt
B186: مصنع شركة ابناء عبدالله عبد المحسن الخضري للصناعات الخرسانية | C186: Abdullah Abdul Mohsen Al-Khodari Co. Factory for Concrete Industries
A187: 33632 | C187: القصيم الثانية
A188: 1110001026 | B188: مصنع شركة تقنية العالم لتعبئة الزيوت | C188: NULL
A189: 1113003789 | B189: مصنع شركة كميت للأعمدة الخرسانية | C189: NULL
A190: 4031050332 | B190: موسسة محمد احمد سليمان الحازمي | C190: Mohamed Ahmed Al-Hazmi Trading Est. (Health Center)
A191: 1010064067 | B191: شركة مصنع آليات النظافة المحدودة | C191: Al-Rubaian Factory Co. for Hand Carts and Janitorial Tasks
A192: 1010084384 | B192: مصنع نافا للمنتجات الهندسية | C192: NAFA Engineering Products Factory
A193: 4604003765 | B193: شركة السلام الدولية المحدودة | C193: NULL
A194: 5855024347 | B194: شركة مصنع دهانات المملكة | C194: Kingdom Paints Factory Co.
A195: 4030187699 | B195: مصنع أحمد عبد ربه الحربي للمبسطات الحديدية | C195: Ahmed Abed Rabbo Military Factory for Flat Iron Bars
A196: 1010209741 | B196: مصنع المنيوم الرياض | C196: Riyadh Aluminium Plant
A197: NULL | B197: مصنع المهيدب للصناعات الغذائية | C197: NULL
A198: 2257038479 | B198: مصنع خليفة خليفة الهاشل للأسلاك الكهربائية | C198: NULL
A199: 5855054594 | B199: مصنع اوركا للابواب والاعمال المعدنية | C199: ORCA Factory for Metal Doors and Products
A200: 3550027488 | B200: مصنع خديجه محمد البلوي لتدوير وتصنيع البلاستيك | C200: NULL
A201: 4650044762 | B201: مصنع مياه أريس | C201: Aris Water Factory
A202: 2051038700 | B202: مصنع شواهد البناء للتحكم الصناعي | C202: NULL
A203: 5855034459 | B203: مصنع ناصر سالم مهدى المهرى | C203: NULL
A204: 4030083606 | B204: مصنع اسلاك اللحام السعودية | C204: NULL
A205: 4030239159 | B205: مصنع شركة الفيحاء الدولية لتدوير المعادن | C205: NULL
A206: 4030109617 | B206: مصنع عبدالحكيم محمد شماخ للمياه المعبأه | C206: NULL
A207: 4030151342 | B207: مصنع المستقبل الباهر للبلاستيك | C207: Al-Mostakbal Al-Baher Plastic Factory
...

Sheet Sheet3
E2: 1010014590 | F2: 494828
E3: 1010073685 | F3: 243061
E4: 1010085734 | F4: 228167
E5: 1010010813 | F5: 220177
E6: 1010029494 | F6: 200175
E7: 1010008551 | F7: 176511
E8: 1010052927 | F8: 150893
E9: 1010014993 | F9: 128869
E10: 1010064131 | F10: 124082
E11: 1010053014 | F11: 94873
E12: 1010061089 | F12: 89974
E13: 1010106953 | F13: 83876
E14: 1010070479 | F14: 80752
E15: 1010071668 | F15: 78345
E16: 1010084155 | F16: 75336
... E601: 1010008540 | F601: 500

Sheet Sheet2
A1: رقم السجل التجاري | B1: رقم العقد | C1: العميل | D1: Name of factories | E1: المدينة | F1: Mobile | G1: Phone | H1: Email | I1: Fax | J1: حالة العميل | K1: نوع الأرض | L1: حالة الإنشائية | M1: تاريخ البدء | N1: تاريخ الإنتهاء | O1: Area | P1: تاريخ إصدار السجل التجاري | Q1: الأنشطة الصناعية
A2: 1010014590 | B2: 800785 | C2: شركة الخزف السعودية | D2: Saudi Ceramic Company | E2: الرياض الثانية | F2: 0504103118 | G2: 0112650265 | H2: alenzie@saudiceramics.com | I2: 0112653333 | J2: مفتوح | K2: صناعي | L2: منتج | M2: 2010-04-13 | N2: 2029-09-06 | O2: 269982 | P2: 28514 | Q2: =VLOOKUP(B2,[1]Sheet1!$A$1:$F$6212,6,0) -> #N/A
A3: 1010085734 | B3: 806537 | C3: مصنع الشركة العربية للانابيب | D3: Arabian Pipes Company | E3: الرياض الثانية | F3: 0503478702 | G3: 0112650123 | H3: info@arabian-pipes.com | I3: 0112650312 | J3: مفتوح | K3: صناعي | L3: منتج | M3: 2014-11-16 | N3: 2034-04-11 | O3: 228167 | P3: 33474 | Q3: =VLOOKUP(B3,[1]Sheet1!$A$1:$F$6212,6,0) -> #N/A
A4: 1010010813 | B4: 806733 | C4: مركز سابك الصناعي | D4: NULL | E4: الرياض الثانية | F4: 0504478143 | G4: 0112503131 | H4: alsherehyf@sabic.com | I4: 0112651101 | J4: مفتوح | K4: صناعي | L4: منتج | M4: 2014-05-08 | N4: 2019-03-15 | O4: 192746 | P4: 28129 | Q4: =VLOOKUP(B4,[1]Sheet1!$A$1:$F$6212,6,0) -> #N/A
A5: 1010029494 | B5: 800350 | C5: الراشد ايه بيوتنج | D5: Al-Rashid Abetong Co. Ltd. | E5: الرياض الثانية | F5: 0503155602 | G5: 0114981222 | H5: ahmed@alrashidabetong.com | I5: 0112792448 | J5: مفتوح | K5: صناعي | L5: منتج | M5: 2009-07-19 | N5: 2019-04-01 | O5: 183576 | P5: 2 | Q5: =VLOOKUP(B5,[1]Sheet1!$A$1:$F$6212,6,0) -> #N/A
A6: 1010008551 | B6: 807131 | C6: مصنع الرياض للأثاث | D6: Riyadh Furniture Industries Factory | E6: الرياض الثانية | F6: 0506424801 | G6: 0114981216 | H6: info@athath.com | I6: 014981216 | J6: مفتوح | K6: صناعي | L6: منتج | M6: 2016-04-07 | N6: 2035-09-01 | O6: 146484 | P6: 27631 | Q6: =VLOOKUP(B6,[1]Sheet1!$A$1:$F$6212,6,0) -> #N/A
A7: 1010064131 | B7: 807391 | C7: مصنع البابطين للاعمدة والصواري المجلفنة وملحقاتها | D7: #N/A | E7: الرياض الثانية | F7: 0505273911 | G7: 0112650003 | H7: kaha-yami@al-babtain.com.sa | I7: 0112651983 | J7: مفتوح | K7: صناعي | L7: منتج | M7: 2016-06-19 | N7: 2032-12-16 | O7: 124082 | P7: 31734 | Q7: =VLOOKUP(B7,[1]Sheet1!$A$1:$F$6212,6,0) -> #N/A
A8: 1010073685 | B8: 807629 | C8: شركة العبداللطيف للأستثمار الصناعي | D8: Al-Abdullatif Industrial Investment Company | E8: الرياض الثانية | F8: 0505757403 | G8: 0112658888 | H8: jaber@carpets.com | I8: 0112659999 | J8: مفتوح | K8: صناعي | L8: منتج | M8: 2016-10-23 | N8: 2030-05-23 | O8: 114917 | P8: 32777 | Q8: =VLOOKUP(B8,[1]Sheet1!$A$1:$F$6212,6,0) -> #N/A
A9: 1010071668 | B9: 805080 | C9: شركة الشاهين للصناعات المعدنية | D9: Al Shaheen Metal Industries Co. | E9: الرياض الثانية | F9: 0505456833 | G9: 0112656565 | H9: ahmed@alshahin.com | I9: 0112651526 | J9: مفتوح | K9: صناعي | L9: منتج | M9: 2014-06-25 | N9: 2033-08-19 | O9: 78345 | P9: 32588 | Q9: =VLOOKUP(B9,[1]Sheet1!$A$1:$F$6212,6,0) -> #N/A
A10: 1010084155 | B10: 807020 | C10: شركة تصنيع مواد التعبئة والتغليف - فيبكو | D10: NULL | E10: الرياض الثانية | F10: 0564994747 | G10: 0112652299 | H10: sms@fipco.com.sa | I10: 0112651275 | J10: مفتوح | K10: صناعي | L10: منتج | M10: 2016-04-30 | N10: 2035-09-24 | O10: 75336 | P10: 33405 | Q10: =VLOOKUP(B10,[1]Sheet1!$A$1:$F$6212,6,0) -> #N/A
A11: 1010057929 | B11: 807304 | C11: مصنع بلاستيك الوطنيه | D11: NULL | E11: الرياض الثانية | F11: 0504818829 | G11: 0112650523 | H11: gs-razak@wataniaind.com | I11: 0112652692 | J11: مفتوح | K11: صناعي | L11: منتج | M11: 2016-10-11 | N11: 2036-03-07 | O11: 66329 | P11: 1/1/53 0:00 | Q11: =VLOOKUP(B11,[1]Sheet1!$A$1:$F$6212,6,0) -> #N/A
A12: 1010070479 | B12: 807351 | C12: الشركة المتحدة للمنتجات الخشبية والمعدنية | D12: NULL | E12: الرياض الثانية | F12: 0505414691 | G12: 0112657777 | H12: info@uwpco.com | I12: 0112652817 | J12: مفتوح | K12: صناعي | L12: منتج | M12: 2016-06-08 | N12: 2022-04-03 | O12: 65776 | P12: 32488 | Q12: =VLOOKUP(B12,[1]Sheet1!$A$1:$F$6212,6,0) -> #N/A
A13: 1010052927 | B13: 21039 | C13: الشركة السعودية الحديثة لصناعة المعادن والكابلات والبلاستيك -الرياض للكابلات والمعادن | D13: Saudi Modern Company for Metals, Cables and Plastic Industry Ltd. (Riyadh Cables and Metals) (RC&M) | E13: الرياض الثانية | F13: 0505232352 | G13: 0112650850 | H13: rcgc@riyadh-cables.com | I13: 0112651423 | J13: مفتوح | K13: صناعي | L13: منتج | M13: 2011-01-01 | N13: 2030-05-27 | O13: 63000 | P13: 2 | Q13: =VLOOKUP(B13,[1]Sheet1!$A$1:$F$6212,6,0) -> #N/A
A14: 1010000320 | B14: 800430 | C14: مصنع معامل الرياض للإنتاج المخملي | D14: Riyadh Labs Factory for the Velvety Production | E14: الرياض الثانية | F14: 0553377774 | G14: 0112651849 | H14: abdullah@rvf.sa | I14: 0112652175 | J14: مفتوح | K14: صناعي | L14: منتج | M14: 2009-08-05 | N14: 2019-04-18 | O14: 60532 | P14: 20972 | Q14: =VLOOKUP(B14,[1]Sheet1!$A$1:$F$6212,6,0) -> #N/A
A15: 1010011738 | B15: 280230 | C15: مصنع الشركة السعودية للطوب الرملي والجيري ومواد البناء | D15: Sand - Lime Brick Factory | E15: الرياض الثانية | F15: 0539404005 | G15: 0112651824 | H15: raedmohmmed@saudilime.com | I15: 0112651175 | J15: مفتوح | K15: صناعي | L15: منتج | M15: 2014-05-13 | N15: 2030-11-09 | O15: 60078 | P15: 28213 | Q15: =VLOOKUP(B15,[1]Sheet1!$A$1:$F$6212,6,0) -> #N/A
A16: 1010049588 | B16: 800463 | C16: شركة الجميح وشل لزيوت التشحيم | D16: Aljomaih and Shell Lubricating Oil Company | E16: الرياض الثانية | F16: 0553678512 | G16: 0112650888 | H16: admin@aljomaihshell.com | I16: 0112650949 | J16: مفتوح | K16: صناعي | L16: منتج | M16: 2009-04-18 | N16: 2018-12-28 | O16: 60000 | P16: 30440 | Q16: =VLOOKUP(B16,[1]Sheet1!$A$1:$F$6212,6,0) -> #N/A
A17: 1010014993 | B17: 800353 | C17: الشركة السعودية لإنتاج الانابيب الفخارية | D17: NULL | E17: الرياض الثانية | F17: 0555333050 | G17: 0114980772 | H17: saad@svcpfactory.com | I17: 0114984815 | J17: مفتوح | K17: صناعي | L17: منتج | M17: 2006-10-30 | N17: 2031-01-30 | O17: 58489 | P17: 28536 | Q17: =VLOOKUP(B17,[1]Sheet1!$A$1:$F$6212,6,0) -> #N/A
A18: 1010009671 | B18: 20675 | C18: شركة المباني الخفيفة - سيبوركس | D18: Light Weight Co. -SIPOREX | E18: الرياض الثانية | F18: 0550002479 | G18: 0114981800 | H18: thamer@lccsiporex.com | I18: 0114982072 | J18: مفتوح | K18: صناعي | L18: منتج | M18: 2002-01-25 | N18: 2026-04-27 | O18: 57560 | P18: 27906 | Q18: =VLOOKUP(B18,[1]Sheet1!$A$1:$F$6212,6,0) -> #N/A
A19: 1010061089 | B19: 290428 | C19: شركة صناعات الخريف | D19: Al-Khorayef Industries Co. | E19: الرياض الثانية | F19: 0503409694 | G19: 0112651124 | H19: factory@alkhorayef.com | I19: 0112652348 | J19: مفتوح | K19: صناعي | L19: منتج | M19: 2008-07-19 | N19: 2030-11-11 | O19: 55533 | P19: 31369 | Q19: =VLOOKUP(B19,[1]Sheet1!$A$1:$F$6212,6,0) -> #N/A
A20: 1010145258 | B20: 804879 | C20: مجمع شركة الفداغي الصناعية | D20: Al-Fadaghi Industrial Company Complex | E20: الرياض الثانية | F20: 0555224242 | G20: 0114953000 | H20: info@alfaddahgi.com | I20: 0114954000 | J20: مفتوح | K20: صناعي | L20: منتج | M20: 2014-03-28 | N20: 2023-12-10 | O20: 54798 | P20: 2 | Q20: =VLOOKUP(B20,[1]Sheet1!$A$1:$F$6212,6,0) -> #N/A
A21: 1010054991 | B21: 808687 | C21: شركة دانيا للأغذية المحدودة | D21: NULL | E21: الرياض الثانية | F21: 0533999097 | G21: 0114981414 | H21: moalt@arlafoods.com | I21: 0114980628 | J21: مفتوح | K21: صناعي | L21: منتج | M21: 2017-08-10 | N21: 2029-04-01 | O21: 54056 | P21: 30853 | Q21: =VLOOKUP(B21,[1]Sheet1!$A$1:$F$6212,6,0) -> #N/A
A22: 1010052201 | B22: 800718 | C22: مجموعة عبدالله شمسان الصناعية | D22: Abdullah Shamsan Industrial Group | E22: الرياض الثانية | F22: 0599919356 | G22: 0112651600 | H22: ahmad@shamsangroup.com | I22: 0112650952 | J22: مفتوح | K22: صناعي | L22: منتج | M22: 2009-11-07 | N22: 2029-04-02 | O22: 53350 | P22: 30648 | Q22: =VLOOKUP(B22,[1]Sheet1!$A$1:$F$6212,6,0) -> #N/A
A23: 1010016778 | B23: 280252 | C23: شركة الدهانات السعودية المحدوده - بينتكو | D23: Saudi Paints Co. | E23: الرياض الثانية | F23: 0505473464 | G23: 0114465555 | H23: Paintco@Paintco.net | I23: 0114460611 | J23: مفتوح | K23: صناعي | L23: منتج | M23: 2007-11-05 | N23: 2031-02-15 | O23: 53075 | P23: 2 | Q23: =VLOOKUP(B23,[1]Sheet1!$A$1:$F$6212,6,0) -> #N/A
... A26: 1010075300 | B26: 804022 | C26: المصنع الوطني لأنتاج العبوات الزجاجية | D26: Saudi National Lighting and Electricity Co. | E26: الرياض الثانية | F26: 0505455753 | G26: 0112652323 | H26: yas@zoujaj-glass.com | I26: 0112651347 | J26: مفتوح | K26: صناعي | L26: منتج | M26: 2013-05-16 | N26: 2032-10-10 | O26: 48454 | P26: 2 | Q26: =VLOOKUP(B26,[1]Sheet1!$A$1:$F$6212,6,0) -> #N/A
A27: 1010061412 | B27: 20153 | C27: شركة أيه بي بي للصناعات الكهربائية | D27: ABB | E27: الرياض الثانية | F27: 0505488292 | G27: 0112653030 | H27: fatahallah.abdulbaqi@sa.abb.com | I27: 0112651211 | J27: مفتوح | K27: صناعي | L27: منتج | M27: 2010-12-30 | N27: 2030-05-25 | O27: 48450 | P27: 1/1/53 0:00 | Q27: =VLOOKUP(B27,[1]Sheet1!$A$1:$F$6212,6,0) -> #N/A
A28: 1010056593 | B28: 290158 | C28: مصنع الجميح لإنتاج العلب | D28: Al-Jomaih Factory for the Production of Cans | E28: الرياض الثانية | F28: 0566669915 | G28: 0112652381 | H28: HTAHER@aljomaihbev.com | I28: 0112651696 | J28: مفتوح | K28: صناعي | L28: منتج | M28: 2008-02-27 | N28: 2030-06-20 | O28: 48000 | P28: 1/1/53 0:00 | Q28: =VLOOKUP(B28,[1]Sheet1!$A$1:$F$6212,6,0) -> #N/A
A29: 1010033645 | B29: 800833 | C29: شركة البلاد للآنابيب الخرسانية المحدودة | D29: NULL | E29: الرياض الثانية | F29: 0504491480 | G29: 0114793531 | H29: info@albiladpipes.com | I29: 0114771372 | J29: مفتوح | K29: صناعي | L29: منتج | M29: 2010-01-23 | N29: 2029-06-19 | O29: 47543 | P29: 29485 | Q29: =VLOOKUP(B29,[1]Sheet1!$A$1:$F$6212,6,0) -> #N/A
A30: - | B30: 808927 | C30: شركة الربيع السعودية للاغذية | D30: Al-Hanaya Restaurant & Supermarket | E30: الرياض الثانية | F30: 0504405214 | G30: 0114980000 | H30: grm@alrabie.com | I30: - | J30: مفتوح | K30: صناعي | L30: منتج | M30: 2017-05-16 | N30: 2030-12-14 | O30: 47126 | P30: 2 | Q30: =VLOOKUP(B30,[1]Sheet1!$A$1:$F$6212,6,0) -> #N/A
A31: 1010106953 | B31: 803849 | C31: الشركة السعودية الحديثة لصناعة الاسلاك والكابلات الكهربائية | D31: Saudi Modern Company for Special Electric Wire & Cables Industry | E31: الرياض الثانية | F31: 0505232352 | G31: 0112650850 | H31: rcgc@riyadh-cables.com | I31: 0112651423 | J31: مفتوح | K31: صناعي | L31: منتج | M31: 2013-05-06 | N31: 2032-09-30 | O31: 46024 | P31: 41753 | Q31: =VLOOKUP(B31,[1]Sheet1!$A$1:$F$6212,6,0) -> #N/A
A32: 1010067273 | B32: 803920 | C32: مصنع الجريسي لصناعة الأثاث | D32: Al- Jeraisy Furniture Factory | E32: الرياض الثانية | F32: 0507839533 | G32: 0114984222 | H32: jff_info@jeraisy.com | I32: 0114982355 | J32: مفتوح | K32: صناعي | L32: منتج | M32: 2014-03-26 | N32: 2032-08-31 | O32: 45000 | P32: 2 | Q32: =VLOOKUP(B32,[1]Sheet1!$A$1:$F$6212,6,0) -> #N/A
A33: 1010139400 | B33: 807043 | C33: مصنع الخضير للصناعات المعدنية | D33: NULL | E33: الرياض الثانية | F33: 0504465224 | G33: 0112652244 | H33: info@alkhodair.com | I33: 0112651294 | J33: مفتوح | K33: صناعي | L33: منتج | M33: 2016-03-15 | N33: 2035-08-09 | O33: 44959 | P33: 35032 | Q33: =VLOOKUP(B33,[1]Sheet1!$A$1:$F$6212,6,0) -> #N/A
A34: 1010029561 | B34: 800403 | C34: المصنع السعودي لأسطوانات الغاز | D34: Saudi Gas Cylinder Factory | E34: الرياض الثانية | F34: 0505450719 | G34: 0112651196 | H34: enagas@enagas.com.sa | I34: 0112652065 | J34: مفتوح | K34: صناعي | L34: منتج | M34: 2014-02-08 | N34: 2018-12-14 | O34: 44250 | P34: 2 | Q34: =VLOOKUP(B34,[1]Sheet1!$A$1:$F$6212,6,0) -> #N/A
A35: 1010026063 | B35: 807709 | C35: الشركة الوطنية المحدودة للجلفنة والأعمدة الحديدية | D35: NULL | E35: الرياض الثانية | F35: 0555458842 | G35: 00966112652078 | H35: Info@galvanco.com | I35: 00966112652079 | J35: مفتوح | K35: صناعي | L35: منتج | M35: 2016-11-14 | N35: 2029-06-25 | O35: 44101 | P35: 28846 | Q35: =VLOOKUP(B35,[1]Sheet1!$A$1:$F$6212,6,0) -> #N/A
A36: 2051000622 | B36: 800398 | C36: مصنع عميقة للفوانيس والأعمدة والجلفنة | D36: National Galvanizing and Coating Company | E36: الرياض الثانية | F36: 0505413790 | G36: 0114984587 | H36: omega@omega-abahsain.com | I36: 0114982383 | J36: مفتوح | K36: صناعي | L36: منتج | M36: 2009-01-04 | N36: 2018-09-16 | O36: 41250 | P36: 31301 | Q36: =VLOOKUP(B36,[1]Sheet1!$A$1:$F$6212,6,0) -> #N/A
A37: 1010006939 | B37: 800369 | C37: شركة المواد العمرانية | D37: NULL | E37: الرياض الثانية | F37: 0563633989 | G37: 0112651837 | H37: almudayfer_group@alomraniah.com | I37: 0112651836 | J37: مفتوح | K37: صناعي | L37: منتج | M37: 2009-06-17 | N37: 2019-02-28 | O37: 40250 | P37: 2 | Q37: =VLOOKUP(B37,[1]Sheet1!$A$1:$F$6212,6,0) -> #N/A
A38: 1010138372 | B38: 807078 | C38: الشركة السعودية للمأكولات الخفيفة المحدودة | D38: Saudi Light Food Co. Ltd. | E38: الرياض الثانية | F38: 0554005464 | G38: 0112018888 | H38: abdullah.al-nafie@pepsico.com | I38: 0112011188 | J38: مفتوح | K38: صناعي | L38: منتج | M38: 2016-03-28 | N38: 2019-02-23 | O38: 40081 | P38: 34987 | Q38: =VLOOKUP(B38,[1]Sheet1!$A$1:$F$6212,6,0) -> #N/A
A39: 1010012057 | B39: 290077 | C39: شركة الانارة السعودية المحدودة | D39: NULL | E39: الرياض الثانية | F39: 0555809749 | G39: 0112651010 | H39: lami@saudilighting.com | I39: 0112652194 | J39: مفتوح | K39: صناعي | L39: منتج | M39: 2008-01-30 | N39: 2030-05-22 | O39: 40050 | P39: 28238 | Q39: =VLOOKUP(B39,[1]Sheet1!$A$1:$F$6212,6,0) -> #N/A
A40: 1010096120 | B40: 807688 | C40: شركة يونيتشارم الخليج للصناعات الصحية المحدودة | D40: Unicharm Gulf Hygienic Industries Company | E40: الرياض الثانية | F40: 0555202393 | G40: 0112651633 | H40: adel-harbi@GulfHygienic.com.sa | I40: 0112651614 | J40: مفتوح | K40: صناعي | L40: منتج | M40: 2016-11-13 | N40: 2036-04-09 | O40: 39006 | P40: 33783 | Q40: =VLOOKUP(B40,[1]Sheet1!$A$1:$F$6212,6,0) -> #N/A
... A50: 1010039827 | B50: 280235 | C50: شركة صناعات العزل العربية - عوازل | D50: Arab Insulation Industries Co. - Insulators | E50: الرياض الثانية | F50: 0505563666 | G50: 0114981604 | H50: hr@awazel.com | I50: 0114981707 | J50: مفتوح | K50: صناعي | L50: منتج | M50: 2007-06-30 | N50: 2030-10-12 | O50: 34500 | P50: 29753 | Q50: =VLOOKUP(B50,[1]Sheet1!$A$1:$F$6212,6,0) -> #N/A
A51: 1010095382 | B51: 808591 | C51: شركة عدوان للصناعات الكيماوية | D51: NULL | E51: الرياض الثانية | F51: 0505466329 | G51: 0112650041 | H51: faisal@adwanchem.com | I51: 0112650023 | J51: مفتوح | K51: صناعي | L51: منتج | M51: 2017-07-18 | N51: 2018-07-07 | O51: 34232 | P51: 1/1/53 0:00 | Q51: =VLOOKUP(B51,[1]Sheet1!$A$1:$F$6212,6,0) -> #N/A
...

Sheet Sheet4
A1: رقم السجل التجاري | B1: رقم العقد | C1: العميل | D1: Name of factories | E1: المدينة | F1: Mobile | G1: Phone | H1: Email | I1: Fax | J1: حالة العميل | K1: نوع الأرض | L1: حالة الإنشائية | M1: تاريخ البدء | N1: تاريخ الإنتهاء | O1: Area | P1: تاريخ إصدار السجل التجاري | Q1: الأنشطة الصناعية
A2: 1010014590 | B2: 800785 | C2: شركة الخزف السعودية | D2: Saudi Ceramic Company | E2: الرياض الثانية | F2: 0504103118 | G2: 0112650265 | H2: alenzie@saudiceramics.com | I2: 0112653333 | J2: مفتوح | K2: صناعي | L2: منتج | M2: 2010-04-13 | N2: 2029-09-06 | O2: 269982 | P2: 28514 | Q2: =VLOOKUP(B2,[1]Sheet1!$A$1:$F$6212,6,0) -> #N/A
A3: 1010085734 | B3: 806537 | C3: مصنع الشركة العربية للانابيب | D3: Arabian Pipes Company | E3: الرياض الثانية | F3: 0503478702 | G3: 0112650123 | H3: info@arabian-pipes.com | I3: 0112650312 | J3: مفتوح | K3: صناعي | L3: منتج | M3: 2014-11-16 | N3: 2034-04-11 | O3: 228167 | P3: 33474 | Q3: =VLOOKUP(B3,[1]Sheet1!$A$1:$F$6212,6,0) -> #N/A
A4: 1010010813 | B4: 806733 | C4: مركز سابك الصناعي | D4: NULL | E4: الرياض الثانية | F4: 0504478143 | G4: 0112503131 | H4: alsherehyf@sabic.com | I4: 0112651101 | J4: مفتوح | K4: صناعي | L4: منتج | M4: 2014-05-08 | N4: 2019-03-15 | O4: 192746 | P4: 28129 | Q4: =VLOOKUP(B4,[1]Sheet1!$A$1:$F$6212,6,0) -> #N/A
A5: 1010029494 | B5: 800350 | C5: الراشد ايه بيوتنج | D5: Al-Rashid Abetong Co. Ltd. | E5: الرياض الثانية | F5: 0503155602 | G5: 0114981222 | H5: ahmed@alrashidabetong.com | I5: 0112792448 | J5: مفتوح | K5: صناعي | L5: منتج | M5: 2009-07-19 | N5: 2019-04-01 | O5: 183576 | P5: 2 | Q5: =VLOOKUP(B5,[1]Sheet1!$A$1:$F$6212,6,0) -> #N/A
A6: 1010008551 | B6: 807131 | C6: مصنع الرياض للأثاث | D6: Riyadh Furniture Industries Factory | E6: الرياض الثانية | F6: 0506424801 | G6: 0114981216 | H6: info@athath.com | I6: 014981216 | J6: مفتوح | K6: صناعي | L6: منتج | M6: 2016-04-07 | N6: 2035-09-01 | O6: 146484 | P6: 27631 | Q6: =VLOOKUP(B6,[1]Sheet1!$A$1:$F$6212,6,0) -> #N/A
A7: 1010064131 | B7: 807391 | C7: مصنع البابطين للاعمدة والصواري المجلفنة وملحقاتها | D7: #N/A | E7: الرياض الثانية | F7: 0505273911 | G7: 0112650003 | H7: kaha-yami@al-babtain.com.sa | I7: 0112651983 | J7: مفتوح | K7: صناعي | L7: منتج | M7: 2016-06-19 | N7: 2032-12-16 | O7: 124082 | P7: 31734 | Q7: =VLOOKUP(B7,[1]Sheet1!$A$1:$F$6212,6,0) -> #N/A
A8: 1010073685 | B8: 807629 | C8: شركة العبداللطيف للأستثمار الصناعي | D8: Al-Abdullatif Industrial Investment Company | E8: الرياض الثانية | F8: 0505757403 | G8: 0112658888 | H8: jaber@carpets.com | I8: 0112659999 | J8: مفتوح | K8: صناعي | L8: منتج | M8: 2016-10-23 | N8: 2030-05-23 | O8: 114917 | P8: 32777 | Q8: =VLOOKUP(B8,[1]Sheet1!$A$1:$F$6212,6,0) -> #N/A
A9: 1010071668 | B9: 805080 | C9: شركة الشاهين للصناعات المعدنية | D9: Al Shaheen Metal Industries Co. | E9: الرياض الثانية | F9: 0505456833 | G9: 0112656565 | H9: ahmed@alshahin.com | I9: 0112651526 | J9: مفتوح | K9: صناعي | L9: منتج | M9: 2014-06-25 | N9: 2033-08-19 | O9: 78345 | P9: 32588 | Q9: =VLOOKUP(B9,[1]Sheet1!$A$1:$F$6212,6,0) -> #N/A
A10: 1010084155 | B10: 807020 | C10: شركة تصنيع مواد التعبئة والتغليف - فيبكو | D10: NULL | E10: الرياض الثانية | F10: 0564994747 | G10: 0112652299 | H10: sms@fipco.com.sa | I10: 0112651275 | J10: مفتوح | K10: صناعي | L10: منتج | M10: 2016-04-30 | N10: 2035-09-24 | O10: 75336 | P10: 33405 | Q10: =VLOOKUP(B10,[1]Sheet1!$A$1:$F$6212,6,0) -> #N/A
A11: 1010057929 | B11: 807304 | C11: مصنع بلاستيك الوطنيه | D11: NULL | E11: الرياض الثانية | F11: 0504818829 | G11: 0112650523 | H11: gs-razak@wataniaind.com | I11: 0112652692 | J11: مفتوح | K11: صناعي | L11: منتج | M11: 2016-10-11 | N11: 2036-03-07 | O11: 66329 | P11: 1/1/53 0:00 | Q11: =VLOOKUP(B11,[1]Sheet1!$A$1:$F$6212,6,0) -> #N/A
A12: 1010070479 | B12: 807351 | C12: الشركة المتحدة للمنتجات الخشبية والمعدنية | D12: NULL | E12: الرياض الثانية | F12: 0505414691 | G12: 0112657777 | H12: info@uwpco.com | I12: 0112652817 | J12: مفتوح | K12: صناعي | L12: منتج | M12: 2016-06-08 | N12: 2022-04-03 | O12: 65776 | P12: 32488 | Q12: =VLOOKUP(B12,[1]Sheet1!$A$1:$F$6212,6,0) -> #N/A
A13: 1010052927 | B13: 21039 | C13: الشركة السعودية الحديثة لصناعة المعادن والكابلات والبلاستيك -الرياض للكابلات والمعادن | D13: Saudi Modern Company for Metals, Cables and Plastic Industry Ltd. (Riyadh Cables and Metals) (RC&M) | E13: الرياض الثانية | F13: 0505232352 | G13: 0112650850 | H13: rcgc@riyadh-cables.com | I13: 0112651423 | J13: مفتوح | K13: صناعي | L13: منتج | M13: 2011-01-01 | N13: 2030-05-27 | O13: 63000 | P13: 2 | Q13: =VLOOKUP(B13,[1]Sheet1!$A$1:$F$6212,6,0) -> #N/A
A14: 1010000320 | B14: 800430 | C14: مصنع معامل الرياض للإنتاج المخملي | D14: Riyadh Labs Factory for the Velvety Production | E14: الرياض الثانية | F14: 0553377774 | G14: 0112651849 | H14: abdullah@rvf.sa | I14: 0112652175 | J14: مفتوح | K14: صناعي | L14: منتج | M14: 2009-08-05 | N14: 2019-04-18 | O14: 60532 | P14: 20972 | Q14: =VLOOKUP(B14,[1]Sheet1!$A$1:$F$6212,6,0) -> #N/A
A15: 1010011738 | B15: 280230 | C15: مصنع الشركة السعودية للطوب الرملي والجيري ومواد البناء | D15: Sand - Lime Brick Factory | E15: الرياض الثانية | F15: 0539404005 | G15: 0112651824 | H15: raedmohmmed@saudilime.com | I15: 0112651175 | J15: مفتوح | K15: صناعي | L15: منتج | M15: 2014-05-13 | N15: 2030-11-09 | O15: 60078 | P15: 28213 | Q15: =VLOOKUP(B15,[1]Sheet1!$A$1:$F$6212,6,0) -> #N/A
A16: 1010049588 | B16: 800463 | C16: شركة الجميح وشل لزيوت التشحيم | D16: Aljomaih and Shell Lubricating Oil Company | E16: الرياض الثانية | F16: 0553678512 | G16: 0112650888 | H16: admin@aljomaihshell.com | I16: 0112650949 | J16: مفتوح | K16: صناعي | L16: منتج | M16: 2009-04-18 | N16: 2018-12-28 | O16: 60000 | P16: 30440 | Q16: =VLOOKUP(B16,[1]Sheet1!$A$1:$F$6212,6,0) -> #N/A
A17: 1010014993 | B17: 800353 | C17: الشركة السعودية لإنتاج الانابيب الفخارية | D17: NULL | E17: الرياض الثانية | F17: 0555333050 | G17: 0114980772 | H17: saad@svcpfactory.com | I17: 0114984815 | J17: مفتوح | K17: صناعي | L17: منتج | M17: 2006-10-30 | N17: 2031-01-30 | O17: 58489 | P17: 28536 | Q17: =VLOOKUP(B17,[1]Sheet1!$A$1:$F$6212,6,0) -> #N/A
A18: 1010009671 | B18: 20675 | C18: شركة المباني الخفيفة - سيبوركس | D18: Light Weight Co. -SIPOREX | E18: الرياض الثانية | F18: 0550002479 | G18: 0114981800 | H18: thamer@lccsiporex.com | I18: 0114982072 | J18: مفتوح | K18: صناعي | L18: منتج | M18: 2002-01-25 | N18: 2026-04-27 | O18: 57560 | P18: 27906 | Q18: =VLOOKUP(B18,[1]Sheet1!$A$1:$F$6212,6,0) -> #N/A
A19: 1010061089 | B19: 290428 | C19: شركة صناعات الخريف | D19: Al-Khorayef Industries Co. | E19: الرياض الثانية | F19: 0503409694 | G19: 0112651124 | H19: factory@alkhorayef.com | I19: 0112652348 | J19: مفتوح | K19: صناعي | L19: منتج | M19: 2008-07-19 | N19: 2030-11-11 | O19: 55533 | P19: 31369 | Q19: =VLOOKUP(B19,[1]Sheet1!$A$1:$F$6212,6,0) -> #N/A
A20: 1010145258 | B20: 804879 | C20: مجمع شركة الفداغي الصناعية | D20: Al-Fadaghi Industrial Company Complex | E20: الرياض الثانية | F20: 0555224242 | G20: 0114953000 | H20: info@alfaddahgi.com | I20: 0114954000 | J20: مفتوح | K20: صناعي | L20: منتج | M20: 2014-03-28 | N20: 2023-12-10 | O20: 54798 | P20: 2 | Q20: =VLOOKUP(B20,[1]Sheet1!$A$1:$F$6212,6,0) -> #N/A
A21: 1010054991 | B21: 808687 | C21: شركة دانيا للأغذية المحدودة | D21: NULL | E21: الرياض الثانية | F21: 0533999097 | G21: 0114981414 | H21: moalt@arlafoods.com | I21: 0114980628 | J21: مفتوح | K21: صناعي | L21: منتج | M21: 2017-08-10 | N21: 2029-04-01 | O21: 54056 | P21: 30853 | Q21: =VLOOKUP(B21,[1]Sheet1!$A$1:$F$6212,6,0) -> #N/A
A22: 1010052201 | B22: 800718 | C22: مجموعة عبدالله شمسان الصناعية | D22: Abdullah Shamsan Industrial Group | E22: الرياض الثانية | F22: 0599919356 | G22: 0112651600 | H22: ahmad@shamsangroup.com | I22: 0112650952 | J22: مفتوح | K22: صناعي | L22: منتج | M22: 2009-11-07 | N22: 2029-04-02 | O22: 53350 | P22: 30648 | Q22: =VLOOKUP(B22,[1]Sheet1!$A$1:$F$6212,6,0) -> #N/A
A23: 1010016778 | B23: 280252 | C23: شركة الدهانات السعودية المحدوده - بينتكو | D23: Saudi Paints Co. | E23: الرياض الثانية | F23: 0505473464 | G23: 0114465555 | H23: Paintco@Paintco.net | I23: 0114460611 | J23: مفتوح | K23: صناعي | L23: منتج | M23: 2007-11-05 | N23: 2031-02-15 | O23: 53075 | P23: 2 | Q23: =VLOOKUP(B23,[1]Sheet1!$A$1:$F$6212,6,0) -> #N/A
... A26: 1010075300 | B26: 804022 | C26: المصنع الوطني لأنتاج العبوات الزجاجية | D26: Saudi National Lighting and Electricity Co. | E26: الرياض الثانية | F26: 0505455753 | G26: 0112652323 | H26: yas@zoujaj-glass.com | I26: 0112651347 | J26: مفتوح | K26: صناعي | L26: منتج | M26: 2013-05-16 | N26: 2032-10-10 | O26: 48454 | P26: 2 | Q26: =VLOOKUP(B26,[1]Sheet1!$A$1:$F$6212,6,0) -> #N/A
A27: 1010061412 | B27: 20153 | C27: شركة أيه بي بي للصناعات الكهربائية | D27: ABB | E27: الرياض الثانية | F27: 0505488292 | G27: 0112653030 | H27: fatahallah.abdulbaqi@sa.abb.com | I27: 0112651211 | J27: مفتوح | K27: صناعي | L27: منتج | M27: 2010-12-30 | N27: 2030-05-25 | O27: 48450 | P27: 1/1/53 0:00 | Q27: =VLOOKUP(B27,[1]Sheet1!$A$1:$F$6212,6,0) -> #N/A
A28: 1010056593 | B28: 290158 | C28: مصنع الجميح لإنتاج العلب | D28: Al-Jomaih Factory for the Production of Cans | E28: الرياض الثانية | F28: 0566669915 | G28: 0112652381 | H28: HTAHER@aljomaihbev.com | I28: 0112651696 | J28: مفتوح | K28: صناعي | L28: منتج | M28: 2008-02-27 | N28: 2030-06-20 | O28: 48000 | P28: 1/1/53 0:00 | Q28: =VLOOKUP(B28,[1]Sheet1!$A$1:$F$6212,6,0) -> #N/A
A29: 1010033645 | B29: 800833 | C29: شركة البلاد للآنابيب الخرسانية المحدودة | D29: NULL | E29: الرياض الثانية | F29: 0504491480 | G29: 0114793531 | H29: info@albiladpipes.com | I29: 0114771372 | J29: مفتوح | K29: صناعي | L29: منتج | M29: 2010-01-23 | N29: 2029-06-19 | O29: 47543 | P29: 29485 | Q29: =VLOOKUP(B29,[1]Sheet1!$A$1:$F$6212,6,0) -> #N/A
